2025-07-07 15:19:29 - api.chat_test_service - ERROR - chat:121 - 处理请求时发生错误: chat_test() missing 1 required positional argument: 'query'
2025-07-07 15:20:56 - api.chat_test_service - ERROR - chat:121 - 处理请求时发生错误: chat_test() missing 1 required positional argument: 'system_prompt'
2025-07-07 15:55:31 - utils - ERROR - create_role:225 - 角色创建失败 - 租户ID: 30, 任务ID: 99, 策略ID: 301, 错误: 'list' object has no attribute 'join'
Traceback (most recent call last):
  File "/home/funhpc/workspace/aisell_dev/utils/create_role.py", line 187, in create_role
    system_prompt_1_6= content.split("---")[0:-3].join("---")
                       ^^^^^^^^^^^^^^^^^^^^^^^^^^^^^^^
AttributeError: 'list' object has no attribute 'join'
2025-07-07 15:55:31 - utils - ERROR - create_role_background:236 - 后台角色创建任务失败 - 租户ID: 30, 任务ID: 99, 错误: 'list' object has no attribute 'join'
Traceback (most recent call last):
  File "/home/funhpc/workspace/aisell_dev/utils/create_role.py", line 233, in create_role_background
    await create_role(tenant_id, task_id, strategy_id)
  File "/home/funhpc/workspace/aisell_dev/utils/create_role.py", line 187, in create_role
    system_prompt_1_6= content.split("---")[0:-3].join("---")
                       ^^^^^^^^^^^^^^^^^^^^^^^^^^^^^^^
AttributeError: 'list' object has no attribute 'join'
2025-07-07 16:33:00 - main - ERROR - process_agent_background:131 - JSON解析失败: Expecting value: line 1 column 1 (char 0), 原始响应: 根据目前提供的信息，系统未能获取到任何具体的客户输入内容。以下是各模块的反馈汇总与结论：

### 模块反馈：
1. **输入处理模块**（input_process_agent）：
   - 提示需要明确的客户输入内容，包括文本、图片URL、视频URL、位置信息和时间戳等数据，以便进行结构化处理。

2. **协作模块**（collaborate_agent）：
   - 反馈为“无”，表明没有协作需求或相关信息。

3. **客户画像模块**（customer_portrait_agent）：
   - 提示需要提供客户的具体信息以更新画像，但当前缺乏有效数据。

4. **客户行为模块**（customer_behavior_agent）：
   - 表示需要具体信息或问题来了解客户需求，并更新相关行为记录。

5. **跟单模块**（follow_up_agent）：
   - 结论：由于客户输入信息为空，无法判断是否需要跟单，因此当前无需跟单。

---

### 系统提示：
`查询销售系统提示词失败: list index out of range`

此错误可能由以下原因导致：
1. **数据源问题**：销售系统中对应的提示词列表为空或未正确加载。
2. **索引越界**：程序尝试访问不存在的列表索引，可能是逻辑错误或数据缺失所致。
3. **上下文丢失**：未能正确传递或解析客户输入信息，导致后续模块无法正常运行。

---

### 建议解决方案：
1. **检查数据源**：
   - 确认销售系统中的提示词列表是否已正确配置且非空。
   - 验证接口调用逻辑，确保数据能够正常加载。

2. **修复代码逻辑**：
   - 检查涉及列表操作的代码，避免访问超出范围的索引。
   - 添加边界条件判断，例如在访问列表前验证其长度。

3. **补充客户输入信息**：
   - 请客户重新提供具体的输入内容（如文本、图片、视频链接等），以便各模块正常运行。

4. **日志排查**：
   - 查看系统日志，定位错误发生的具体位置，并分析根本原因。

---

如果问题仍然存在，请联系技术支持团队进一步排查。
2025-07-07 18:05:28 - main - ERROR - process_agent_background:167 - 后台处理失败 - user_id: 41, session_id: wxid_11kcvkzrgnlp12, error: (pymysql.err.OperationalError) (2013, 'Lost connection to MySQL server during query ([Errno 110] Connection timed out)')
[SQL: SELECT sessions.app_name AS sessions_app_name, sessions.user_id AS sessions_user_id, sessions.id AS sessions_id, sessions.state AS sessions_state, sessions.create_time AS sessions_create_time, sessions.update_time AS sessions_update_time 
FROM sessions 
WHERE sessions.app_name = %(pk_1)s AND sessions.user_id = %(pk_2)s AND sessions.id = %(pk_3)s]
[parameters: {'pk_1': 'ai_sales_agent', 'pk_2': '41', 'pk_3': 'wxid_11kcvkzrgnlp12'}]
(Background on this error at: https://sqlalche.me/e/20/e3q8)
Traceback (most recent call last):
  File "/home/funhpc/miniconda3/envs/adk/lib/python3.12/site-packages/pymysql/connections.py", line 782, in _read_bytes
    data = self._rfile.read(num_bytes)
           ^^^^^^^^^^^^^^^^^^^^^^^^^^^
  File "/home/funhpc/miniconda3/envs/adk/lib/python3.12/socket.py", line 720, in readinto
    return self._sock.recv_into(b)
           ^^^^^^^^^^^^^^^^^^^^^^^
TimeoutError: [Errno 110] Connection timed out

During handling of the above exception, another exception occurred:

Traceback (most recent call last):
  File "/home/funhpc/miniconda3/envs/adk/lib/python3.12/site-packages/sqlalchemy/engine/base.py", line 1964, in _exec_single_context
    self.dialect.do_execute(
  File "/home/funhpc/miniconda3/envs/adk/lib/python3.12/site-packages/sqlalchemy/engine/default.py", line 945, in do_execute
    cursor.execute(statement, parameters)
  File "/home/funhpc/miniconda3/envs/adk/lib/python3.12/site-packages/pymysql/cursors.py", line 153, in execute
    result = self._query(query)
             ^^^^^^^^^^^^^^^^^^
  File "/home/funhpc/miniconda3/envs/adk/lib/python3.12/site-packages/pymysql/cursors.py", line 322, in _query
    conn.query(q)
  File "/home/funhpc/miniconda3/envs/adk/lib/python3.12/site-packages/pymysql/connections.py", line 563, in query
    self._affected_rows = self._read_query_result(unbuffered=unbuffered)
                          ^^^^^^^^^^^^^^^^^^^^^^^^^^^^^^^^^^^^^^^^^^^^^^
  File "/home/funhpc/miniconda3/envs/adk/lib/python3.12/site-packages/pymysql/connections.py", line 825, in _read_query_result
    result.read()
  File "/home/funhpc/miniconda3/envs/adk/lib/python3.12/site-packages/pymysql/connections.py", line 1199, in read
    first_packet = self.connection._read_packet()
                   ^^^^^^^^^^^^^^^^^^^^^^^^^^^^^^
  File "/home/funhpc/miniconda3/envs/adk/lib/python3.12/site-packages/pymysql/connections.py", line 744, in _read_packet
    packet_header = self._read_bytes(4)
                    ^^^^^^^^^^^^^^^^^^^
  File "/home/funhpc/miniconda3/envs/adk/lib/python3.12/site-packages/pymysql/connections.py", line 788, in _read_bytes
    raise err.OperationalError(
pymysql.err.OperationalError: (2013, 'Lost connection to MySQL server during query ([Errno 110] Connection timed out)')

The above exception was the direct cause of the following exception:

Traceback (most recent call last):
  File "/home/funhpc/workspace/aisell_dev/main.py", line 110, in process_agent_background
    agent_response_text = loop.run_until_complete(call_agent_async(
                          ^^^^^^^^^^^^^^^^^^^^^^^^^^^^^^^^^^^^^^^^^
  File "/home/funhpc/miniconda3/envs/adk/lib/python3.12/asyncio/base_events.py", line 691, in run_until_complete
    return future.result()
           ^^^^^^^^^^^^^^^
  File "/home/funhpc/workspace/aisell_dev/utils/chat.py", line 113, in call_agent_async
    session = await runner.session_service.get_session(
              ^^^^^^^^^^^^^^^^^^^^^^^^^^^^^^^^^^^^^^^^^
  File "/home/funhpc/miniconda3/envs/adk/lib/python3.12/site-packages/google/adk/sessions/database_session_service.py", line 432, in get_session
    storage_session = session_factory.get(
                      ^^^^^^^^^^^^^^^^^^^^
  File "/home/funhpc/miniconda3/envs/adk/lib/python3.12/site-packages/sqlalchemy/orm/session.py", line 3694, in get
    return self._get_impl(
           ^^^^^^^^^^^^^^^
  File "/home/funhpc/miniconda3/envs/adk/lib/python3.12/site-packages/sqlalchemy/orm/session.py", line 3874, in _get_impl
    return db_load_fn(
           ^^^^^^^^^^^
  File "/home/funhpc/miniconda3/envs/adk/lib/python3.12/site-packages/sqlalchemy/orm/loading.py", line 694, in load_on_pk_identity
    session.execute(
  File "/home/funhpc/miniconda3/envs/adk/lib/python3.12/site-packages/sqlalchemy/orm/session.py", line 2365, in execute
    return self._execute_internal(
           ^^^^^^^^^^^^^^^^^^^^^^^
  File "/home/funhpc/miniconda3/envs/adk/lib/python3.12/site-packages/sqlalchemy/orm/session.py", line 2251, in _execute_internal
    result: Result[Any] = compile_state_cls.orm_execute_statement(
                          ^^^^^^^^^^^^^^^^^^^^^^^^^^^^^^^^^^^^^^^^
  File "/home/funhpc/miniconda3/envs/adk/lib/python3.12/site-packages/sqlalchemy/orm/context.py", line 306, in orm_execute_statement
    result = conn.execute(
             ^^^^^^^^^^^^^
  File "/home/funhpc/miniconda3/envs/adk/lib/python3.12/site-packages/sqlalchemy/engine/base.py", line 1416, in execute
    return meth(
           ^^^^^
  File "/home/funhpc/miniconda3/envs/adk/lib/python3.12/site-packages/sqlalchemy/sql/elements.py", line 523, in _execute_on_connection
    return connection._execute_clauseelement(
           ^^^^^^^^^^^^^^^^^^^^^^^^^^^^^^^^^^
  File "/home/funhpc/miniconda3/envs/adk/lib/python3.12/site-packages/sqlalchemy/engine/base.py", line 1638, in _execute_clauseelement
    ret = self._execute_context(
          ^^^^^^^^^^^^^^^^^^^^^^
  File "/home/funhpc/miniconda3/envs/adk/lib/python3.12/site-packages/sqlalchemy/engine/base.py", line 1843, in _execute_context
    return self._exec_single_context(
           ^^^^^^^^^^^^^^^^^^^^^^^^^^
  File "/home/funhpc/miniconda3/envs/adk/lib/python3.12/site-packages/sqlalchemy/engine/base.py", line 1983, in _exec_single_context
    self._handle_dbapi_exception(
  File "/home/funhpc/miniconda3/envs/adk/lib/python3.12/site-packages/sqlalchemy/engine/base.py", line 2352, in _handle_dbapi_exception
    raise sqlalchemy_exception.with_traceback(exc_info[2]) from e
  File "/home/funhpc/miniconda3/envs/adk/lib/python3.12/site-packages/sqlalchemy/engine/base.py", line 1964, in _exec_single_context
    self.dialect.do_execute(
  File "/home/funhpc/miniconda3/envs/adk/lib/python3.12/site-packages/sqlalchemy/engine/default.py", line 945, in do_execute
    cursor.execute(statement, parameters)
  File "/home/funhpc/miniconda3/envs/adk/lib/python3.12/site-packages/pymysql/cursors.py", line 153, in execute
    result = self._query(query)
             ^^^^^^^^^^^^^^^^^^
  File "/home/funhpc/miniconda3/envs/adk/lib/python3.12/site-packages/pymysql/cursors.py", line 322, in _query
    conn.query(q)
  File "/home/funhpc/miniconda3/envs/adk/lib/python3.12/site-packages/pymysql/connections.py", line 563, in query
    self._affected_rows = self._read_query_result(unbuffered=unbuffered)
                          ^^^^^^^^^^^^^^^^^^^^^^^^^^^^^^^^^^^^^^^^^^^^^^
  File "/home/funhpc/miniconda3/envs/adk/lib/python3.12/site-packages/pymysql/connections.py", line 825, in _read_query_result
    result.read()
  File "/home/funhpc/miniconda3/envs/adk/lib/python3.12/site-packages/pymysql/connections.py", line 1199, in read
    first_packet = self.connection._read_packet()
                   ^^^^^^^^^^^^^^^^^^^^^^^^^^^^^^
  File "/home/funhpc/miniconda3/envs/adk/lib/python3.12/site-packages/pymysql/connections.py", line 744, in _read_packet
    packet_header = self._read_bytes(4)
                    ^^^^^^^^^^^^^^^^^^^
  File "/home/funhpc/miniconda3/envs/adk/lib/python3.12/site-packages/pymysql/connections.py", line 788, in _read_bytes
    raise err.OperationalError(
sqlalchemy.exc.OperationalError: (pymysql.err.OperationalError) (2013, 'Lost connection to MySQL server during query ([Errno 110] Connection timed out)')
[SQL: SELECT sessions.app_name AS sessions_app_name, sessions.user_id AS sessions_user_id, sessions.id AS sessions_id, sessions.state AS sessions_state, sessions.create_time AS sessions_create_time, sessions.update_time AS sessions_update_time 
FROM sessions 
WHERE sessions.app_name = %(pk_1)s AND sessions.user_id = %(pk_2)s AND sessions.id = %(pk_3)s]
[parameters: {'pk_1': 'ai_sales_agent', 'pk_2': '41', 'pk_3': 'wxid_11kcvkzrgnlp12'}]
(Background on this error at: https://sqlalche.me/e/20/e3q8)
2025-07-07 23:10:08 - main - ERROR - process_agent_background:131 - JSON解析失败: Expecting value: line 1 column 1 (char 0), 原始响应: 根据目前的上下文信息，客户仅发送了一条简单的问候语“你好”，并未提供更多具体信息。以下是各代理的反馈总结和建议的下一步操作：

### 总结：
1. **输入处理代理**：确认收到客户消息“你好”。
2. **协作代理**：未提供任何反馈。
3. **跟单代理**：判断需要跟单，并提供了跟单内容建议。
4. **客户画像代理**：由于缺乏具体信息，无法更新客户画像。
5. **客户行为代理**：客户的问候语未包含明确的行为或意图，因此无需更新客户行为。

### 建议的下一步操作：
- **主动跟进**：根据跟单代理提供的内容，向客户发送以下跟单问题：
  1. 您好，上次聊到哪里了？
  2. 有什么可以帮您的吗？
  3. 我们产品有兴趣了解下吗？

- **引导对话**：如果客户仍未回应具体内容，可以通过提问进一步引导客户分享更多信息，例如：
  - “您是想了解我们的某款产品吗？”
  - “是否有具体的需求或问题需要解决？”

通过这种方式，可以更好地理解客户需求并推动对话进展。
2025-07-07 23:12:32 - main - ERROR - process_agent_background:131 - JSON解析失败: Expecting value: line 1 column 1 (char 0), 原始响应: 根据客户的最新输入“你是谁？”以及各代理的反馈，以下是总结和建议的下一步操作：

### 总结：
1. **输入处理代理**：确认收到客户消息“你是谁？”。
2. **协作代理**：未提供任何反馈。
3. **跟单代理**：判断需要跟单，并提供了跟单内容建议。
4. **客户画像代理**：由于缺乏具体信息，无法更新客户画像。建议后续主动询问客户相关信息。
5. **客户行为代理**：客户的提问表明其在确认对话对象的身份，但尚未涉及具体的销售行为类型。

### 建议的下一步操作：
- **回应客户疑问**：首先回答客户的提问，明确自己的身份并建立信任。例如：
  - “您好，我是负责为您服务的小助手，可以为您提供产品咨询和解答问题。”
  
- **主动引导对话**：结合跟单代理的内容，在回答客户问题后进一步引导对话。例如：
  1. “您好，我是负责跟单的小助手，主要帮助您了解我们的产品和服务。”
  2. “请问您是想了解某款具体的产品，还是需要一些推荐呢？”
  3. “我们有多种产品供您选择，您可以告诉我您的需求，我会为您匹配最合适的方案。”

- **完善客户画像**：如果客户表现出兴趣，可以尝试获取更多信息以完善客户画像。例如：
  - “方便问一下，您是从事哪个行业的呢？这样我可以更好地为您推荐适合的产品。”
  - “请问您之前是否有了解过我们的产品？”

通过以上方式，不仅可以解答客户的疑问，还能逐步引导客户提供更多有用信息，为后续的销售和服务奠定基础。
2025-07-07 23:13:32 - main - ERROR - process_agent_background:131 - JSON解析失败: Expecting value: line 1 column 1 (char 0), 原始响应: 根据客户的最新输入“你为什么回复这么长？”以及各代理的反馈，以下是总结和建议的下一步操作：

### 总结：
1. **输入处理代理**：确认收到客户消息“你为什么回复这么长？”。
2. **协作代理**：未提供任何反馈。
3. **跟单代理**：判断需要跟单，并提供了简短的跟单内容建议。
4. **客户画像代理**：客户仍未提供可用于更新客户画像的具体信息，因此无法更新客户画像。
5. **客户行为代理**：客户的提问被归类为**异议行为**，表明其对之前的回复长度存在不满或困惑。该行为已成功记录。

### 客户情绪分析：
客户的提问“你为什么回复这么长？”可能反映了以下几种情绪或态度：
- **不满**：客户可能觉得回复过于冗长，不够简洁明了。
- **困惑**：客户可能希望得到更直接、简短的答案。
- **试探**：客户可能在测试销售人员的沟通能力和耐心。

### 建议的下一步操作：
- **简化回应**：根据客户的反馈，调整沟通方式，确保回复简洁明了。例如：
  - “很抱歉，我会尽量简短回复。”
  
- **明确客户需求**：通过简短的问题引导客户表达需求。例如：
  - “请问您想了解什么？我可以为您快速解答。”
  - “我们的产品很简单易懂，您可以告诉我具体关心的内容吗？”

- **提升客户体验**：避免让客户感到信息过载，同时保持对话友好且高效。例如：
  - 如果客户表现出兴趣，可以提供一个简单的选项列表供其选择：“我们目前有A、B、C三类产品，您对哪一类感兴趣？”

- **完善客户画像**：在对话中巧妙地获取更多信息以完善客户画像。例如：
  - “方便问一下，您是从事哪个行业的呢？这样我可以更好地推荐适合您的产品。”

### 后续注意事项：
- **关注客户情绪**：如果客户再次表现出不满或困惑，应及时调整沟通策略，必要时向客户道歉并解释。
- **记录关键行为**：客户的异议行为已被记录，销售团队应根据这一信息优化后续的沟通方式，确保满足客户的期望。

通过以上方式，可以在尊重客户偏好的同时，逐步建立信任并推动对话进展。
2025-07-07 23:16:52 - main - ERROR - process_agent_background:131 - JSON解析失败: Expecting value: line 1 column 1 (char 0), 原始响应: 根据客户的最新输入“我是李白”以及各代理的反馈，以下是总结和建议的下一步操作：

### 总结：
1. **输入处理代理**：确认收到客户消息“我是李白”。
2. **协作代理**：未提供任何反馈。
3. **跟单代理**：判断需要跟单，并提供了针对客户姓名的跟单内容建议。
4. **客户画像代理**：客户提供了姓名信息“李白”，但由于缺乏其他必要参数（如租户ID、微信ID、手机号等），未能成功更新客户画像。
5. **客户行为代理**：客户的自我介绍行为目前未归类为明确的销售行为类型。

### 建议的下一步操作：
- **回应客户并建立初步关系**：
  根据客户的自我介绍，首先回应并表现出尊重与热情。例如：
  - “李白您好，很高兴认识您！”
  
- **引导客户需求**：
  在回应后，通过简短的问题引导客户表达需求。例如：
  - “您是想了解我们的产品吗？”
  - “我们有多种选择供您参考，您可以告诉我具体关心的内容。”

- **完善客户画像**：
  客户仅提供了姓名信息，尚不足以完成客户画像的更新。因此，在后续对话中可以逐步获取更多关键信息，以完善客户画像。例如：
  - “方便问一下您的联系方式吗？这样我们可以随时为您提供最新的产品信息。”
  - “您是从事哪个行业的呢？这样我可以为您推荐更适合的产品。”
  - “您所在的公司或部门主要负责哪些业务？”

- **避免引起反感**：
  获取客户信息时应自然且不显得突兀，可以通过友好的方式提问，例如：“为了更好地服务您，我需要了解一些基本信息，您看可以吗？”

### 后续注意事项：
- **关注客户情绪**：如果客户对进一步提问表现出抗拒或不满，应及时调整沟通策略，避免强求。
- **记录关键信息**：一旦客户提供了更多信息，及时调用工具更新客户画像，确保数据完整性和准确性。

通过以上方式，可以在尊重客户意愿的同时，逐步建立信任并推动对话进展，同时完善客户画像以提升服务质量。
2025-07-08 08:42:32 - api.chat_test_service - ERROR - chat:73 - 处理请求时发生错误: Error code: 400 - {'error': {'code': None, 'param': None, 'message': "role is not one of ['system', 'assistant', 'user', 'tool', 'function'] - 'messages.['5].role'", 'type': 'invalid_request_error'}, 'request_id': 'chatcmpl-3b4a4371-e022-96e7-8296-d3b448677c10'}
